Workbook

Sheet Feuille 1

Sheet Responses
A1: Date de soumission | B1: ID Unique | C1: Score Lead (0-100) | D1: Segment Client | E1: Statut | F1: Code Promo | G1: Statut Code | H1: Valeur (FCFA) | I1: Date Expiration | J1: Code Utilisé | K1: Date Utilisation | L1: Type Utilisateur | M1: Quartier/Zone | N1: Pays (Diaspora) | O1: Tranche d'âge | P1: Taille du foyer | Q1: Situation professionnelle | R1: Lieux d'achat habituels | S1: Fréquence courses | T1: Budget hebdomadaire | U1: Défis rencontrés | V1: Plats sénégalais préférés | W1: Fréquence cuisine maison | X1: Qui cuisine | Y1: Délai commande préféré | Z1: Intérêt commande auto | AA1: Avantages anticipés | AB1: Délai idéal | AC1: Intérêt (1-5) | AD1: Aspects attractifs | AE1: Service préféré | AF1: Prix min acceptable | AG1: Prix max acceptable | AH1: Prix livraison max | AI1: Fréquence utilisation prévue | AJ1: Panier moyen estimé | AK1: Suggestions générales | AL1: Inquiétudes | AM1: Zones famille Sénégal | AN1: Fonctionnalités essentielles | AO1: Types produits souhaités | AP1: Préférence organisation commande | AQ1: Frais service acceptable | AR1: Fréquence utilisation diaspora | AS1: Nombre de foyers à aider | AT1: Téléphone | AU1: Email | AV1: Prénom | AW1: Beta testeur | AX1: Besoins courses alimentaires (Diaspora) | AY1: Défis envoi courses/repas (Diaspora) | AZ1: Panier surprise idéal (Diaspora) | BA1: Recommandation (Diaspora) | BB1: Services complémentaires souhaités (Local) | BC1: Autres services détail (Local) | BD1: Recommandation (Local) | BE1: Semaine | BF1: Mois | BG1: Services Souhaites | BH1: Recommandation Locale | BI1: Promo Code | BJ1: Date Added | BK1: Week Number | BL1: Month
A2: 45908.032 | B2: LKT1757285144378 | C2: 40 | D2: Warm Lead 🌡️ | E2: Nouveau | F2: LK776499J8 | G2: active | H2: 2000 | I2: 2026-03-06T22:45:41.262Z | J2: FALSE | L2: etranger | M2: Diaspora | N2: europe | O2: 36-45 | P2: 7+ | Q2: salarie | R2: N/A | S2: N/A | T2: N/A | U2: N/A | V2: N/A | Y2: N/A | Z2: N/A | AM2: liberte-hlm | AN2: [Ljava.lang.Object;@27e241b0 | AO2: produits_necessite | AP2: je_choisis | AQ2: fixe | AR2: hebdo | AS2: 2 | AT2: 33617777764 | AU2: kbijou31@gmail.com | AV2: Bijou | AW2: TRUE | AY2: confiance_qualite | BA2: certainement | BE2: 37 | BF2: September 2025
A3: 45921.802 | B3: LKT1758474926780 | C3: 55 | D3: Warm Lead 🌡️ | E3: Nouveau | F3: LK8532J0SS | G3: active | H3: 2000 | I3: 2026-03-20T17:15:21.504Z | J3: FALSE | L3: senegal | M3: yoff | O3: 18-25 | P3: 7+ | Q3: salarie | R3: marche_traditionnel, supermarche, boutique_quartier | S3: quotidien | T3: <10000 | U3: temps, prix | V3: yassa, mafe, thiou, domoda, caldou, ceebujenblanc, firire | W3: quotidien | X3: aide | Y3: flexible | Z3: non | AA3: reduction, livraison_gratuite, priorite | AB3: 2h | AC3: 3 | AD3: qualite, prix_transparents, hub_proximite | AE3: mixte | AF3: 5000 | AG3: 10000 | AH3: 1500 | AI3: occasionnel | AJ3: 7500-10000 | AK3: ✅ | AL3: fraicheur, delai_24h, prix, choix | AT3: 784828532 | AU3: ndiayemamediarra093@gmail.com | AV3: Sakura | AW3: TRUE | BB3: resto_partenaire, cosmetiques | BD3: certainement | BE3: 39 | BF3: September 2025
A4: 45921.804 | B4: LKT1758475087325 | C4: 20 | D4: Cold Lead ❄️ | E4: Nouveau | F4: LK0003ZSUP | G4: active | H4: 2000 | I4: 2026-03-20T17:18:03.219Z | J4: FALSE | L4: etranger | M4: Diaspora | N4: europe | O4: 26-35 | P4: 45813 | Q4: salarie | R4: N/A | S4: N/A | T4: N/A | U4: N/A | V4: N/A | Y4: N/A | Z4: N/A | AM4: hors-dakar | AN4: confirmation_sms, photos_produits, suivi_temps_reel, service_client | AO4: produits_necessite, produits_locaux, articles_enfants | AP4: je_choisis | AQ4: fixe | AR4: mensuel | AS4: 1 | AT4: 33769480003 | AV4: Ndeye Awa | AW4: FALSE | AY4: qualite_fraicheur, fiabilite_livraison, delais_longs | BA4: certainement | BE4: 39 | BF4: September 2025
A5: 45921.809 | B5: LKT1758475465909 | C5: 90 | D5: Hot Lead 🔥 | E5: Nouveau | F5: LK77529G2B | G5: active | H5: 2000 | I5: 2026-03-20T17:24:22.506Z | J5: FALSE | L5: senegal | M5: parcelles | O5: 26-35 | P5: 45750 | Q5: etudiant | R5: marche_traditionnel, supermarche, boutique_quartier, vendeur_ambulant, online | S5: quotidien | T5: <10000 | U5: foule | V5: thieboudienne | W5: quotidien | X5: partage | Y5: flexible | Z5: oui_hebdo | AA5: livraison_gratuite | AB5: 2h | AC5: 5 | AD5: gain_temps, qualite, prix_transparents | AE5: livraison | AF5: 2000 | AG5: 3000 | AH5: 1000 | AI5: quotidien | AJ5: 3000-5000 | AL5: prix, aucune | AT5: 784307752 | AW5: TRUE | BB5: pharmacie, boulangerie | BD5: certainement | BE5: 39 | BF5: September 2025
A6: 45921.813 | B6: LKT1758475869012 | C6: 70 | D6: Hot Lead 🔥 | E6: Nouveau | F6: LK50582L1C | G6: active | H6: 2000 | I6: 2026-03-20T17:31:05.668Z | J6: FALSE | L6: senegal | M6: almadies | O6: 26-35 | P6: 45750 | Q6: salarie | R6: marche_traditionnel, supermarche, boutique_quartier | S6: bimensuel | T6: 35000-50000 | U6: temps, qualite, disponibilite | W6: 2-3fois | X6: partage | Y6: 48h | Z6: oui_mensuel | AA6: reduction, creneau, points | AB6: 48h | AC6: 4 | AD6: gain_temps, commande_avance | AE6: livraison | AF6: 6000 | AG6: 8500 | AH6: 1000 | AI6: bimensuel | AJ6: 15000+ | AL6: fraicheur, choix, paiement | AT6: 776575058 | AV6: Lune | AW6: FALSE | BB6: pharmacie | BD6: certainement | BE6: 39 | BF6: September 2025
A7: 45921.813 | B7: LKT1758475879408 | C7: 68 | D7: Warm Lead 🌡️ | E7: Nouveau | F7: LK5947YHB9 | G7: active | H7: 2000 | I7: 2026-03-20T17:31:16.449Z | J7: FALSE | L7: senegal | M7: parcelles | O7: 18-25 | P7: 2 | Q7: entrepreneur | R7: boutique_quartier | S7: quotidien | T7: <10000 | U7: temps | V7: thieboudienne | W7: occasionnel | X7: moi | Y7: flexible | Z7: oui_personnalise | AA7: reduction, priorite | AB7: peu_importe | AC7: 5 | AD7: packs_recettes | AE7: livraison | AF7: 5000 | AG7: 7000 | AH7: variable | AI7: 1-2fois | AJ7: 3000-5000 | AL7: aucune | AT7: 772395947 | AU7: amy947538@gmail.com | AV7: Amy Badara Ndiaye | AW7: FALSE | BB7: resto_partenaire | BD7: certainement | BE7: 39 | BF7: September 2025
A8: 45921.823 | B8: LKT1758476689857 | C8: 70 | D8: Hot Lead 🔥 | E8: Nouveau | F8: LK287919DD | G8: active | H8: 2000 | I8: 2026-03-20T17:44:46.158Z | J8: FALSE | L8: senegal | M8: autre | O8: 26-35 | P8: 45813 | Q8: entrepreneur | R8: boutique_quartier | S8: hebdo | T8: 20000-35000 | U8: prix | V8: yassa | W8: quotidien | X8: aide | Y8: 72h | Z8: oui_bi_hebdo | AA8: priorite | AB8: meme_jour | AC8: 4 | AD8: packs_recettes | AE8: mixte | AF8: 5000 | AG8: 8000 | AH8: variable | AI8: 3-4fois | AJ8: 3000-5000 | AL8: delai_24h | AT8: 774622879 | AU8: mouhasow252@gmail.com | AV8: Mamadou Moustapha Sow | AW8: FALSE | BB8: produits_menagers | BD8: probablement | BE8: 39 | BF8: September 2025
A9: 45921.83 | B9: LKT1758477307326 | C9: 20 | D9: Cold Lead ❄️ | E9: Nouveau | F9: LK60561LPL | G9: active | H9: 2000 | I9: 2026-03-20T17:55:04.651Z | J9: FALSE | L9: etranger | M9: Diaspora | N9: europe | O9: 18-25 | P9: 45813 | Q9: etudiant | R9: N/A | S9: N/A | T9: N/A | U9: N/A | V9: N/A | Y9: N/A | Z9: N/A | AM9: liberte-hlm | AN9: confirmation_sms, message_personnel, suivi_temps_reel, service_client | AO9: packs_recettes, produits_necessite, paniers_surprise | AP9: consultation_proches | AQ9: 5 | AR9: mensuel | AS9: 1 | AT9: 778446056 | AW9: FALSE | AY9: qualite_fraicheur, fiabilite_livraison | BA9: certainement | BE9: 39 | BF9: September 2025
A10: 45921.841 | B10: LKT1758478238948 | C10: 70 | D10: Hot Lead 🔥 | E10: Nouveau | F10: LK8976MXSI | G10: active | H10: 2000 | I10: 2026-03-20T18:10:33.157Z | J10: FALSE | L10: senegal | M10: almadies | O10: 26-35 | P10: 1 | Q10: entrepreneur | R10: supermarche | S10: mensuel | T10: 10000-20000 | U10: transport | W10: occasionnel | X10: restaurant | Y10: 24h | Z10: oui_mensuel | AA10: reduction, livraison_gratuite, personnalisation | AB10: meme_jour | AC10: 5 | AD10: gain_temps | AE10: livraison | AF10: 10000 | AG10: 15000 | AH10: variable | AI10: occasionnel | AJ10: 10000-15000 | AL10: fraicheur | AT10: 781378976 | AU10: smondiaye@gmail.com | AV10: Seydina | AW10: TRUE | BB10: resto_partenaire, cosmetiques, produits_menagers, boulangerie | BD10: probablement | BE10: 39 | BF10: September 2025
A11: 45921.85 | B11: LKT1758479062790 | C11: 30 | D11: Cold Lead ❄️ | E11: Nouveau | F11: LK9128EODG | G11: active | H11: 2000 | I11: 2026-03-20T18:24:19.523Z | J11: FALSE | L11: etranger | M11: Diaspora | N11: europe | O11: 46-55 | P11: 45813 | Q11: entrepreneur | R11: N/A | S11: N/A | T11: N/A | U11: N/A | V11: N/A | Y11: N/A | Z11: N/A | AM11: parcelles-grand-dakar | AN11: confirmation_sms, photos_produits, suivi_temps_reel, service_client | AO11: produits_necessite | AP11: je_choisis | AQ11: 0 | AR11: mensuel | AS11: 1 | AT11: 771129128 | AW11: TRUE | AX11: Panier mensuel des denrées de base, première nécessité avec en plus poulet viande pour tenir le mois | AY11: qualite_fraicheur, fiabilite_livraison, cout_total | BA11: probablement | BE11: 39 | BF11: September 2025
A12: 45921.851 | B12: LKT1758479098549 | C12: 45 | D12: Warm Lead 🌡️ | E12: Nouveau | F12: LK7393LMUS | G12: active | H12: 2000 | I12: 2026-03-20T18:24:55.927Z | J12: FALSE | L12: etranger | M12: Diaspora | N12: europe | O12: 46-55 | P12: 7+ | Q12: entrepreneur | R12: N/A | S12: N/A | T12: N/A | U12: N/A | V12: N/A | Y12: N/A | Z12: N/A | AM12: plateau-almadies, parcelles-grand-dakar | AN12: confirmation_sms, photos_produits, message_personnel | AO12: produits_necessite, produits_locaux | AP12: je_choisis | AQ12: fixe | AR12: occasionnel | AS12: 45750 | AT12: 33678777393 | AU12: nanoufall@yahoo.fr | AV12: Marème | AW12: TRUE | AX12: Un pack de produits | AY12: qualite_fraicheur | AZ12: Poisson, viande, légumes, fruits etc | BA12: certainement | BE12: 39 | BF12: September 2025
A13: 45921.854 | B13: LKT1758479386197 | C13: 35 | D13: Cold Lead ❄️ | E13: Nouveau | F13: LK39434ELZ | G13: active | H13: 2000 | I13: 2026-03-20T18:29:43.416Z | J13: FALSE | L13: etranger | M13: Diaspora | N13: europe | O13: 18-25 | P13: 45750 | Q13: salarie | R13: N/A | S13: N/A | T13: N/A | U13: N/A | V13: N/A | Y13: N/A | Z13: N/A | AM13: guediawaye | AN13: confirmation_sms, photos_produits, suivi_temps_reel | AO13: packs_recettes, produits_necessite, paniers_surprise | AP13: proches_choisissent | AQ13: fixe | AR13: mensuel | AS13: 1 | AT13: 221771473943 | AU13: coulibalykhady1510@gmail.com | AV13: Khady | AW13: TRUE | AY13: qualite_fraicheur, fiabilite_livraison, choix_panier | AZ13: Poissons , viande, riz | BA13: certainement | BE13: 39 | BF13: September 2025
A14: 45921.856 | B14: LKT1758479562861 | C14: 20 | D14: Cold Lead ❄️ | E14: Nouveau | F14: LK85989UXL | G14: active | H14: 2000 | I14: 2026-03-20T18:32:39.823Z | J14: FALSE | L14: etranger | M14: Diaspora | N14: europe | O14: 36-45 | P14: 7+ | Q14: salarie | R14: N/A | S14: N/A | T14: N/A | U14: N/A | V14: N/A | Y14: N/A | Z14: N/A | AM14: hors-dakar | AN14: confirmation_sms, photos_produits, suivi_temps_reel, service_client | AO14: produits_necessite | AP14: je_choisis | AQ14: 5 | AR14: mensuel | AS14: 1 | AT14: 775208598 | AW14: FALSE | AY14: qualite_fraicheur, fiabilite_livraison, choix_panier, delais_longs | BA14: certainement | BE14: 39 | BF14: September 2025
A15: 45921.861 | B15: LKT1758480003305 | C15: 15 | D15: Cold Lead ❄️ | E15: Nouveau | F15: LK0803ALQ4 | G15: active | H15: 2000 | I15: 2026-03-20T18:39:59.686Z | J15: FALSE | L15: etranger | M15: Diaspora | N15: europe | O15: 18-25 | P15: 2 | Q15: salarie | R15: N/A | S15: N/A | T15: N/A | U15: N/A | V15: N/A | Y15: N/A | Z15: N/A | AM15: guediawaye | AN15: confirmation_sms, photos_produits, suivi_temps_reel, service_client | AO15: produits_necessite, produits_locaux, articles_enfants | AP15: proches_choisissent | AQ15: 5 | AR15: occasionnel | AS15: 1 | AT15: 33643620803 | AW15: FALSE | AX15: Faire des packs surprises | AY15: qualite_fraicheur, fiabilite_livraison, choix_panier, cout_total | AZ15: Poisson frais légumes fruits fruits et du riz ainsi que de la viande et quelques épices | BA15: probablement | BE15: 39 | BF15: September 2025
A16: 45921.865 | B16: LKT1758480355749 | C16: 15 | D16: Cold Lead ❄️ | E16: Nouveau | F16: LK3239JDJ0 | G16: active | H16: 2000 | I16: 2026-03-20T18:45:53.086Z | J16: FALSE | L16: etranger | M16: Diaspora | N16: europe | O16: 36-45 | P16: 45750 | Q16: entrepreneur | R16: N/A | S16: N/A | T16: N/A | U16: N/A | V16: N/A | Y16: N/A | Z16: N/A | AM16: point-e-fann | AN16: confirmation_sms, suivi_temps_reel | AO16: produits_necessite, paniers_surprise | AP16: consultation_proches | AQ16: fixe | AR16: occasionnel | AS16: 1 | AT16: 33766513239 | AW16: FALSE | AY16: qualite_fraicheur, fiabilite_livraison | BA16: probablement | BE16: 39 | BF16: September 2025
A17: 45921.868 | B17: LKT1758480565229 | C17: 45 | D17: Warm Lead 🌡️ | E17: Nouveau | F17: LK9653X4E4 | G17: active | H17: 2000 | I17: 2026-03-20T18:49:22.641Z | J17: FALSE | L17: etranger | M17: Diaspora | N17: europe | O17: 26-35 | P17: 45813 | Q17: etudiant | R17: N/A | S17: N/A | T17: N/A | U17: N/A | V17: N/A | Y17: N/A | Z17: N/A | AM17: hors-dakar | AN17: confirmation_sms, photos_produits, suivi_temps_reel | AO17: paniers_surprise, produits_locaux, articles_enfants | AP17: je_choisis | AQ17: fixe | AR17: occasionnel | AS17: 5+ | AT17: 771879653 | AU17: mariacire.sng@gmail.com | AV17: Mari | AW17: TRUE | AY17: qualite_fraicheur, fiabilite_livraison, choix_panier | AZ17: Poisson, jus locaux | BA17: certainement | BE17: 39 | BF17: September 2025
A18: 45921.878 | B18: LKT1758481462220 | C18: 20 | D18: Cold Lead ❄️ | E18: Nouveau | F18: LK8870N2Y3 | G18: active | H18: 2000 | I18: 2026-03-20T19:04:19.577Z | J18: FALSE | L18: etranger | M18: Diaspora | N18: europe | O18: 18-25 | P18: 7+ | Q18: etudiant | R18: N/A | S18: N/A | T18: N/A | U18: N/A | V18: N/A | Y18: N/A | Z18: N/A | AM18: yoff-ngor | AN18: photos_produits, suivi_temps_reel | AO18: packs_recettes, produits_necessite, paniers_surprise, produits_locaux | AP18: proches_choisissent | AQ18: 10 | AR18: occasionnel | AS18: 1 | AT18: 33766428870 | AU18: adjiaidatoure@gmail.com | AV18: Adji | AW18: FALSE | AY18: fiabilite_livraison | BA18: certainement | BE18: 39 | BF18: September 2025
A19: 45921.886 | B19: LKT1758482114882 | C19: 70 | D19: Hot Lead 🔥 | E19: Nouveau | F19: LK1616FWAC | G19: active | H19: 2000 | I19: 2026-03-20T19:15:11.612Z | J19: FALSE | L19: senegal | M19: autre | O19: 46-55 | P19: 45813 | Q19: salarie | R19: supermarche | S19: hebdo | T19: 35000-50000 | U19: temps | V19: ceebujenblanc | W19: 2-3fois | X19: conjoint | Y19: 48h | Z19: oui_mensuel | AA19: reduction, livraison_gratuite, personnalisation | AB19: meme_jour | AC19: 4 | AD19: gain_temps | AE19: livraison | AF19: 4000 | AG19: 5000 | AH19: 0 | AI19: bimensuel | AJ19: 5000-7500 | AL19: fraicheur, prix | AT19: 774371616 | AW19: FALSE | BB19: produits_menagers | BD19: certainement | BE19: 39 | BF19: September 2025
A20: 45921.93 | B20: LKT1758485966998 | C20: 48 | D20: Warm Lead 🌡️ | E20: Nouveau | F20: LK6327K8VA | G20: active | H20: 2000 | I20: 2026-03-20T20:19:23.766Z | J20: FALSE | L20: senegal | M20: hors_dakar | O20: 56+ | P20: 7+ | Q20: retraite | R20: boutique_quartier | S20: hebdo | T20: 10000-20000 | U20: qualite, prix, disponibilite | V20: thieboudienne, yassa, mafe, thiou, supkanja, caldou, bassi | W20: quotidien | X20: partage | Y20: 24h | Z20: oui_mensuel | AA20: reduction, livraison_gratuite, priorite | AB20: 24h | AC20: 3 | AD20: prix_transparents, hub_proximite, commande_avance | AE20: mixte | AF20: 3500 | AG20: 4000 | AH20: 500 | AI20: 1-2fois | AJ20: 3000-5000 | AL20: fraicheur, prix, choix | AT20: 221776316327 | AW20: FALSE | BB20: produits_menagers, boulangerie | BD20: certainement | BE20: 39 | BF20: September 2025
A21: 45921.944 | B21: LKT1758487156824 | C21: 20 | D21: Cold Lead ❄️ | E21: Nouveau | F21: LK0628XNQ8 | G21: active | H21: 2000 | I21: 2026-03-20T20:39:13.954Z | J21: FALSE | L21: etranger | M21: Diaspora | N21: europe | O21: 36-45 | P21: 7+ | Q21: entrepreneur | R21: N/A | S21: N/A | T21: N/A | U21: N/A | V21: N/A | Y21: N/A | Z21: N/A | AM21: hors-dakar | AN21: confirmation_sms, photos_produits | AO21: packs_recettes | AP21: proches_choisissent | AQ21: fixe | AR21: fetes | AS21: 1 | AT21: 764150628 | AW21: FALSE | AY21: choix_panier | BA21: certainement | BE21: 39 | BF21: September 2025
A22: 45921.946 | B22: LKT1758487299240 | C22: 35 | D22: Cold Lead ❄️ | E22: Nouveau | F22: LK9808VRN6 | G22: active | H22: 2000 | I22: 2026-03-20T20:41:36.619Z | J22: FALSE | L22: etranger | M22: Diaspora | N22: europe | O22: 18-25 | P22: 7+ | Q22: etudiant | R22: N/A | S22: N/A | T22: N/A | U22: N/A | V22: N/A | Y22: N/A | Z22: N/A | AM22: mermoz-sacre-coeur | AN22: confirmation_sms, photos_produits, suivi_temps_reel | AO22: paniers_surprise | AP22: je_choisis | AQ22: 0 | AR22: occasionnel | AS22: 2 | AT22: 221771589808 | AU22: dykha2106@outlook.com | AV22: Khady | AW22: TRUE | AX22: Offrir un pack surprise | AY22: qualite_fraicheur, fiabilite_livraison, cout_total, delais_longs | AZ22: Légumes frais, jus exotique et des fruits | BA22: probablement | BE22: 39 | BF22: September 2025
A23: 45921.95 | B23: LKT1758487647475 | C23: 100 | D23: Hot Lead 🔥 | E23: Nouveau | F23: LK9294RXYX | G23: active | H23: 2000 | I23: 2026-03-20T20:47:24.195Z | J23: FALSE | L23: senegal | M23: ouakam | O23: 26-35 | P23: 45813 | Q23: menagere | R23: marche_traditionnel, supermarche, boutique_quartier | S23: hebdo | T23: 35000-50000 | U23: prix, disponibilite | V23: thieboudienne, yassa, thiou, ceebujenblanc | W23: 2-3fois | X23: moi | Y23: 24h | Z23: oui_personnalise | AA23: reduction, livraison_gratuite, priorite | AB23: 2h | AC23: 5 | AD23: gain_temps, qualite, prix_transparents | AE23: mixte | AF23: 3000 | AG23: 8000 | AH23: variable | AI23: 1-2fois | AJ23: 15000+ | AL23: fraicheur, prix, choix | AT23: 781399294 | AW23: TRUE | BB23: produits_menagers | BC23: Fruits frais | BD23: certainement | BE23: 39 | BF23: September 2025
A24: 45921.95 | B24: LKT1758487671555 | C24: 10 | D24: Cold Lead ❄️ | E24: Nouveau | F24: LK78964GI5 | G24: active | H24: 2000 | I24: 2026-03-20T20:47:48.536Z | J24: FALSE | L24: etranger | M24: Diaspora | N24: europe | O24: 46-55 | P24: 45813 | Q24: entrepreneur | R24: N/A | S24: N/A | T24: N/A | U24: N/A | V24: N/A | Y24: N/A | Z24: N/A | AM24: hors-dakar | AN24: confirmation_sms | AO24: produits_necessite | AP24: proches_choisissent | AQ24: 5 | AR24: occasionnel | AS24: 1 | AT24: 760187896 | AW24: FALSE | AY24: choix_panier | BA24: peut_etre | BE24: 39 | BF24: September 2025
A25: 45921.964 | B25: LKT1758488923679 | C25: 35 | D25: Cold Lead ❄️ | E25: Nouveau | F25: LK309117Z4 | G25: active | H25: 2000 | I25: 2026-03-20T21:08:39.919Z | J25: FALSE | L25: etranger | M25: Diaspora | N25: europe | O25: 26-35 | P25: 7+ | Q25: salarie | R25: N/A | S25: N/A | T25: N/A | U25: N/A | V25: N/A | Y25: N/A | Z25: N/A | AM25: liberte-hlm | AN25: confirmation_sms, photos_produits, suivi_temps_reel | AO25: packs_recettes, produits_necessite, produits_locaux | AP25: je_choisis | AR25: fetes | AS25: 5+ | AT25: 775383091 | AU25: khndiaye000@gmail.com | AV25: Khadijatou | AW25: TRUE | AX25: Offrir un pack surprise | AY25: qualite_fraicheur, fiabilite_livraison, choix_panier | AZ25: Jus locaux et les fruits | BA25: peut_etre | BE25: 39 | BF25: September 2025
A26: 45921.975 | B26: LKT1758489831972 | C26: 30 | D26: Cold Lead ❄️ | E26: Nouveau | F26: LK0682MOJJ | G26: active | H26: 2000 | I26: 2026-03-20T21:23:47.813Z | J26: FALSE | L26: etranger | M26: Diaspora | N26: europe | O26: 26-35 | P26: 7+ | Q26: entrepreneur | R26: N/A | S26: N/A | T26: N/A | U26: N/A | V26: N/A | Y26: N/A | Z26: N/A | AM26: hors-dakar | AN26: confirmation_sms, photos_produits, service_client | AO26: produits_necessite, produits_locaux | AP26: je_choisis | AQ26: 0 | AR26: mensuel | AS26: 45750 | AT26: 221762460682 | AW26: FALSE | AY26: qualite_fraicheur, fiabilite_livraison, cout_total | BA26: certainement | BE26: 39 | BF26: September 2025
A27: 45922.041 | B27: LKT1758495571669 | C27: 20 | D27: Cold Lead ❄️ | E27: Nouveau | F27: LK6540KONC | G27: active | H27: 2000 | I27: 2026-03-20T22:59:28.673Z | J27: FALSE | L27: etranger | M27: Diaspora | N27: europe | O27: 26-35 | P27: 7+ | Q27: salarie | R27: N/A | S27: N/A | T27: N/A | U27: N/A | V27: N/A | Y27: N/A | Z27: N/A | AM27: hors-dakar | AN27: confirmation_sms, photos_produits, suivi_temps_reel, service_client | AO27: packs_recettes, paniers_surprise, produits_locaux | AP27: je_choisis | AQ27: fixe | AR27: fetes | AS27: 1 | AT27: 33753706540 | AU27: papakebetiate@gmail.com | AV27: Mamadou | AW27: FALSE | AY27: choix_panier, cout_total | BA27: certainement | BE27: 39 | BF27: September 2025
A28: 45922.094 | B28: LKT1758500110363 | C28: 90 | D28: Hot Lead 🔥 | E28: Nouveau | F28: LK4934KIZ2 | G28: active | H28: 2000 | I28: 2026-03-21T00:15:02.573Z | J28: FALSE | L28: senegal | M28: autre | O28: 18-25 | P28: 45813 | Q28: etudiant | R28: online | S28: hebdo | T28: 20000-35000 | U28: transport | V28: yassa | W28: quotidien | X28: restaurant | Y28: 24h | Z28: oui_hebdo | AA28: reduction | AB28: meme_jour | AC28: 4 | AD28: qualite, prix_transparents | AE28: click_collect | AF28: 10000 | AG28: 200000 | AH28: 1000 | AI28: 3-4fois | AJ28: <3000 | AL28: delai_24h | AT28: 707124934 | AU28: @gmail.com | AV28: Amicollè | AW28: TRUE | BD28: certainement | BE28: 39 | BF28: September 2025
A29: 45922.095 | B29: LKT1758500179220 | C29: 90 | D29: Hot Lead 🔥 | E29: Nouveau | F29: LK2597M6VX | G29: active | H29: 2000 | I29: 2026-03-21T00:16:14.350Z | J29: FALSE | L29: senegal | M29: parcelles | O29: 18-25 | P29: 1 | Q29: salarie | R29: boutique_quartier | S29: 2-3fois | T29: <10000 | U29: prix | V29: thieboudienne, yassa, mafe, thiou, domoda, caldou, ceebujenblanc | W29: 2-3fois | X29: moi | Y29: flexible | Z29: oui_mensuel | AA29: reduction, livraison_gratuite, priorite | AB29: meme_jour | AC29: 5 | AD29: gain_temps, packs_recettes, qualite | AE29: hub_direct | AF29: 500 | AG29: 600 | AH29: 0 | AI29: quotidien | AJ29: <3000 | AL29: fraicheur | AT29: 221788512597 | AU29: khadija@20 | AV29: Khadija faye | AW29: TRUE | BB29: resto_partenaire, pharmacie | BD29: certainement | BE29: 39 | BF29: September 2025
A30: 45922.15 | B30: LKT1758504989432 | C30: 80 | D30: Hot Lead 🔥 | E30: Nouveau | F30: LK40727K04 | G30: active | H30: 2000 | I30: 2026-03-21T01:36:24.315Z | J30: FALSE | L30: senegal | M30: ouakam | O30: 26-35 | P30: 45750 | Q30: entrepreneur | R30: supermarche | S30: 2-3fois | T30: 10000-20000 | U30: temps | V30: yassa, mafe, domoda, ceebujenblanc, pastels, fataya | W30: 4-5fois | X30: partage | Y30: flexible | Z30: oui_bi_hebdo | AA30: livraison_gratuite | AB30: 2h | AC30: 4 | AD30: packs_recettes | AE30: mixte | AF30: 5000 | AG30: 7000 | AH30: 0 | AI30: quotidien | AJ30: 7500-10000 | AL30: fraicheur | AT30: 778184072 | AU30: arameba47@gmail.com | AV30: Arame | AW30: TRUE | BB30: cosmetiques | BD30: certainement | BE30: 39 | BF30: September 2025
A31: 45922.183 | B31: LKT1758507772127 | C31: 75 | D31: Hot Lead 🔥 | E31: Nouveau | F31: LK7176ZCRD | G31: active | H31: 2000 | I31: 2026-03-21T02:22:47.791Z | J31: FALSE | L31: senegal | M31: hors_dakar | O31: 18-25 | P31: 7+ | Q31: etudiant | R31: boutique_quartier | S31: quotidien | T31: 10000-20000 | U31: qualite, prix, disponibilite, foule | V31: thieboudienne, yassa, mafe, thiou, domoda, supkanja, caldou | W31: quotidien | X31: partage | Y31: flexible | Z31: oui_hebdo | AA31: reduction, livraison_gratuite, priorite | AB31: meme_jour | AC31: 4 | AD31: packs_recettes, qualite, prix_transparents | AE31: livraison | AF31: 5000 | AG31: 10000 | AH31: 500 | AI31: quotidien | AJ31: 3000-5000 | AL31: fraicheur, delai_24h, livraison, paiement | AT31: 787187176 | AU31: fatimataboudiwa@gmail.com | AW31: TRUE | BB31: produits_menagers, pharmacie, boulangerie, autre | BD31: probablement | BE31: 39 | BF31: September 2025
A32: 45922.354 | B32: LKT1758522542729 | C32: 20 | D32: Cold Lead ❄️ | E32: Nouveau | F32: LK60263FZ2 | G32: active | H32: 2000 | I32: 2026-03-21T06:28:35.324Z | J32: FALSE | L32: etranger | M32: Diaspora | N32: europe | O32: 18-25 | P32: 45813 | Q32: salarie | R32: N/A | S32: N/A | T32: N/A | U32: N/A | V32: N/A | Y32: N/A | Z32: N/A | AM32: guediawaye | AN32: confirmation_sms, photos_produits, message_personnel, suivi_temps_reel, service_client | AO32: paniers_surprise, articles_enfants | AP32: proches_choisissent | AQ32: 0 | AR32: occasionnel | AS32: 1 | AT32: 33780806026 | AU32: seyealassanelaye@gmail.com | AV32: Alassane | AW32: FALSE | AX32: Offrir un pack surprise | AY32: qualite_fraicheur, fiabilite_livraison, choix_panier, cout_total, delais_longs | AZ32: Pas d’idée particulière, je me baserai sur les propositions de pack surprise SUGGESTION : Proposer un coté panier solidaire et cibler certains familles qui n’arrivent pas à s’en sortir pour manger ou autre. Et je pense qu’il y’aura pas mal de volontaires qui voudront juste faites des dons. | BA32: certainement | BE32: 39 | BF32: September 2025
A33: 45922.401 | B33: LKT1758526677708 | C33: 85 | D33: Hot Lead 🔥 | E33: Nouveau | F33: LK8080I8OV | G33: active | H33: 2000 | I33: 2026-03-21T07:37:53.775Z | J33: FALSE | L33: senegal | M33: almadies | O33: 56+ | P33: 7+ | Q33: entrepreneur | R33: marche_traditionnel, supermarche | S33: mensuel | T33: 75000+ | U33: qualite | V33: supkanja, caldou | W33: weekend | X33: aide | Y33: flexible | Z33: oui_personnalise | AA33: personnalisation | AB33: 24h | AC33: 4 | AD33: qualite | AE33: livraison | AF33: 5000 | AG33: 6000 | AH33: variable | AI33: bimensuel | AJ33: 15000+ | AL33: fraicheur | AT33: 767608080 | AV33: Elka | AW33: TRUE | BB33: produits_menagers | BD33: certainement | BE33: 39 | BF33: September 2025
A34: 45922.452 | B34: LKT1758531056072 | C34: 68 | D34: Warm Lead 🌡️ | E34: Nouveau | F34: LK2337ZAQD | G34: active | H34: 2000 | I34: 2026-03-21T08:50:52.210Z | J34: FALSE | L34: senegal | M34: autre | O34: 46-55 | P34: 7+ | Q34: salarie | R34: marche_traditionnel, supermarche, boutique_quartier | S34: hebdo | T34: 20000-35000 | U34: temps, foule | V34: thieboudienne, domoda, supkanja, caldou, bassi, ceebujenblanc, firire | W34: 2-3fois | X34: partage | Y34: flexible | Z34: oui_personnalise | AA34: reduction, livraison_gratuite, creneau | AB34: 24h | AC34: 4 | AD34: gain_temps, qualite, prix_transparents | AE34: livraison | AF34: 5000 | AG34: 7000 | AH34: 1500 | AI34: 1-2fois | AJ34: 15000+ | AL34: fraicheur, prix, choix, paiement | AT34: 221776392337 | AW34: FALSE | BB34: boulangerie | BD34: certainement | BE34: 39 | BF34: September 2025
A35: 45922.663 | B35: LKT1758549271385 | C35: 40 | D35: Warm Lead 🌡️ | E35: Nouveau | F35: LK6668MKON | G35: active | H35: 2000 | I35: 2026-03-21T13:54:27.063Z | J35: FALSE | L35: etranger | M35: Diaspora | N35: europe | O35: 18-25 | P35: 45813 | Q35: menagere | R35: N/A | S35: N/A | T35: N/A | U35: N/A | V35: N/A | Y35: N/A | Z35: N/A | AM35: liberte-hlm | AN35: confirmation_sms, message_personnel, service_client | AO35: produits_necessite, paniers_surprise, produits_locaux | AP35: je_choisis | AQ35: fixe | AR35: occasionnel | AS35: 2 | AT35: 33610536668 | AU35: yassdia688@gmail.com | AV35: Yacine | AW35: TRUE | AY35: qualite_fraicheur, choix_panier, cout_total | AZ35: Fruits ,fromage , charcuterie , cafe , thé , biscuits pour le goûter , confiture , chocolat , beurre | BA35: certainement | BE35: 39 | BF35: September 2025
A36: 45922.674 | B36: LKT1758550227382 | C36: 100 | D36: Hot Lead 🔥 | E36: Nouveau | F36: LK87250TZW | G36: active | H36: 2000 | I36: 2026-03-21T14:10:24.147Z | J36: FALSE | L36: senegal | M36: ouakam | O36: 56+ | P36: 45813 | Q36: entrepreneur | R36: supermarche | S36: bimensuel | T36: 35000-50000 | U36: temps, qualite, disponibilite | V36: thieboudienne, yassa, thiou, supkanja, bassi, firire, fataya | W36: 4-5fois | X36: partage | Y36: flexible | Z36: oui_bi_hebdo | AA36: reduction, livraison_gratuite, creneau | AB36: 2h | AC36: 4 | AD36: gain_temps, qualite, commande_avance | AE36: livraison | AF36: 7000 | AG36: 7000 | AH36: variable | AI36: 3-4fois | AJ36: 10000-15000 | AL36: fraicheur | AT36: 221776328725 | AU36: seydounly2002@yahoo.fr | AV36: Seydou | AW36: TRUE | BB36: produits_menagers | BD36: certainement | BE36: 39 | BF36: September 2025
A37: 45922.758 | B37: LKT1758557516748 | C37: 25 | D37: Cold Lead ❄️ | E37: Nouveau | F37: LK5545F02O | G37: active | H37: 2000 | I37: 2026-03-21T16:11:54.337Z | J37: FALSE | L37: etranger | M37: Diaspora | N37: europe | O37: 18-25 | P37: 1 | Q37: etudiant | R37: N/A | S37: N/A | T37: N/A | U37: N/A | V37: N/A | Y37: N/A | Z37: N/A | AM37: hors-dakar | AN37: confirmation_sms, photos_produits, message_personnel, service_client | AO37: paniers_surprise, produits_locaux | AP37: consultation_proches | AQ37: 10 | AR37: occasionnel | AS37: 2 | AT37: 22795555545 | AW37: FALSE | AY37: qualite_fraicheur, fiabilite_livraison, delais_longs | AZ37: Produits exotiques, denrées alimentaires | BA37: certainement | BE37: 39 | BF37: September 2025
A38: 45922.761 | B38: LKT1758557734134 | C38: 80 | D38: Hot Lead 🔥 | E38: Nouveau | F38: LK49030VNJ | G38: active | H38: 2000 | I38: 2026-03-21T16:15:31.337Z | J38: FALSE | L38: senegal | M38: almadies | O38: 18-25 | P38: 7+ | Q38: salarie | R38: supermarche, boutique_quartier | S38: mensuel | T38: 50000-75000 | U38: transport, prix, foule | V38: thieboudienne, yassa, ceebujenblanc, firire, pastels, fataya | W38: quotidien | X38: aide | Y38: 24h | Z38: oui_mensuel | AA38: livraison_gratuite, priorite | AB38: 24h | AC38: 5 | AD38: gain_temps, qualite, prix_transparents | AE38: livraison | AF38: 5000 | AG38: 7000 | AH38: 0 | AI38: occasionnel | AJ38: 15000+ | AL38: aucune | AT38: 771044903 | AV38: Mame awa | AW38: FALSE | BB38: produits_menagers | BD38: certainement | BE38: 39 | BF38: September 2025
A39: 45922.799 | B39: LKT1758561014886 | C39: 15 | D39: Cold Lead ❄️ | E39: Nouveau | F39: LK6481UH3G | G39: active | H39: 2000 | I39: 2026-03-21T17:10:11.008Z | J39: FALSE | L39: etranger | M39: Diaspora | N39: europe | O39: 18-25 | P39: 7+ | Q39: salarie | R39: N/A | S39: N/A | T39: N/A | U39: N/A | V39: N/A | Y39: N/A | Z39: N/A | AM39: mermoz-sacre-coeur, ouakam | AN39: confirmation_sms, photos_produits, message_personnel, suivi_temps_reel, service_client | AO39: packs_recettes, produits_locaux | AP39: proches_choisissent | AQ39: fixe | AR39: occasionnel | AS39: 1 | AT39: 33629276481 | AU39: barbosaawa@gmail.com | AV39: Awa | AW39: FALSE | AY39: qualite_fraicheur, fiabilite_livraison, cout_total | BA39: probablement | BE39: 39 | BF39: September 2025
A40: 45922.803 | B40: LKT1758561374562 | C40: 25 | D40: Cold Lead ❄️ | E40: Nouveau | F40: LK1403YOOT | G40: active | H40: 2000 | I40: 2026-03-21T17:16:11.458Z | J40: FALSE | L40: etranger | M40: Diaspora | N40: europe | O40: 18-25 | P40: 7+ | Q40: etudiant | R40: N/A | S40: N/A | T40: N/A | U40: N/A | V40: N/A | Y40: N/A | Z40: N/A | AM40: plateau-almadies | AN40: photos_produits, message_personnel, suivi_temps_reel, service_client | AO40: paniers_surprise | AP40: je_choisis | AQ40: 10 | AR40: occasionnel | AS40: 1 | AT40: 771491403 | AV40: Ousmane | AW40: TRUE | AY40: choix_panier | BA40: peut_etre | BE40: 39 | BF40: September 2025
...

Sheet Analytics
A1: Tableau de Bord - Leeket Survey
A3: Métrique | B3: Valeur | C3: Objectif | D3: % Atteint
A4: Total Réponses | B4: =COUNTA(Responses!A:A)-1 -> 66 | C4: 500 | D4: =B4/C4 -> 0.132
A5: Hot Leads (70+) | B5: =COUNTIF(Responses!C:C,">=70") -> #ERROR! | C5: 150 | D5: =B5/C5 -> #ERROR!
A6: Warm Leads (40-69) | B6: =COUNTIFS(Responses!C:C,">=40",Responses!C:C,"<70") -> #ERROR! | C6: 200 | D6: =B6/C6 -> #ERROR!
A7: Cold Leads (<40) | B7: =COUNTIF(Responses!C:C,"<40") -> #ERROR! | C7: -
A8: Score Lead Moyen | B8: =IFERROR(AVERAGE(Responses!C:C),0) -> #ERROR! | C8: 60 | D8: =B8/C8 -> #ERROR!
A9: Beta Testeurs | B9: =COUNTIF(Responses!AV:AV,TRUE) -> #ERROR! | C9: 100 | D9: =B9/C9 -> #ERROR!
A10: Membres Diaspora | B10: =COUNTIF(Responses!L:L,"etranger") -> #ERROR! | C10: 50 | D10: =B10/C10 -> #ERROR!
A11: Taux Conversion Hot | B11: =IFERROR(B5/B4,0) -> #ERROR! | C11: 0.3 | D11: =B11/C11 -> #ERROR!
A13: Top 5 Quartiers | B13: Nombre
A14: =IFERROR(INDEX(SORT(UNIQUE(FILTER(Responses!M:M,Responses!M:M<>"Quartier/Zone",Responses!M:M<>"",Responses!M:M<>"Diaspora")),1,TRUE),1),"N/A") -> #ERROR! | B14: =IFERROR(COUNTIF(Responses!M:M,A14),0) -> #ERROR!
A15: =IFERROR(INDEX(SORT(UNIQUE(FILTER(Responses!M:M,Responses!M:M<>"Quartier/Zone",Responses!M:M<>"",Responses!M:M<>"Diaspora")),1,TRUE),2),"N/A") -> #ERROR! | B15: =IFERROR(COUNTIF(Responses!M:M,A15),0) -> #ERROR!
A16: =IFERROR(INDEX(SORT(UNIQUE(FILTER(Responses!M:M,Responses!M:M<>"Quartier/Zone",Responses!M:M<>"",Responses!M:M<>"Diaspora")),1,TRUE),3),"N/A") -> #ERROR! | B16: =IFERROR(COUNTIF(Responses!M:M,A16),0) -> #ERROR!
A17: =IFERROR(INDEX(SORT(UNIQUE(FILTER(Responses!M:M,Responses!M:M<>"Quartier/Zone",Responses!M:M<>"",Responses!M:M<>"Diaspora")),1,TRUE),4),"N/A") -> #ERROR! | B17: =IFERROR(COUNTIF(Responses!M:M,A17),0) -> #ERROR!
A18: =IFERROR(INDEX(SORT(UNIQUE(FILTER(Responses!M:M,Responses!M:M<>"Quartier/Zone",Responses!M:M<>"",Responses!M:M<>"Diaspora")),1,TRUE),5),"N/A") -> #ERROR! | B18: =IFERROR(COUNTIF(Responses!M:M,A18),0) -> #ERROR!
A20: Tendance 7 derniers jours
A21: Date | B21: Nouvelles réponses | C21: Hot Leads | D21: Diaspora
A22: =TODAY()-6 -> 45921 | B22: =COUNTIFS(Responses!A:A,">="&A22,Responses!A:A,"<"&A22+1) -> #ERROR! | C22: =COUNTIFS(Responses!A:A,">="&A22,Responses!A:A,"<"&A22+1,Responses!C:C,">=70") -> #ERROR! | D22: =COUNTIFS(Responses!A:A,">="&A22,Responses!A:A,"<"&A22+1,Responses!L:L,"etranger") -> #ERROR!
A23: =TODAY()-5 -> 45922 | B23: =COUNTIFS(Responses!A:A,">="&A23,Responses!A:A,"<"&A23+1) -> #ERROR! | C23: =COUNTIFS(Responses!A:A,">="&A23,Responses!A:A,"<"&A23+1,Responses!C:C,">=70") -> #ERROR! | D23: =COUNTIFS(Responses!A:A,">="&A23,Responses!A:A,"<"&A23+1,Responses!L:L,"etranger") -> #ERROR!
A24: =TODAY()-4 -> 45923 | B24: =COUNTIFS(Responses!A:A,">="&A24,Responses!A:A,"<"&A24+1) -> #ERROR! | C24: =COUNTIFS(Responses!A:A,">="&A24,Responses!A:A,"<"&A24+1,Responses!C:C,">=70") -> #ERROR! | D24: =COUNTIFS(Responses!A:A,">="&A24,Responses!A:A,"<"&A24+1,Responses!L:L,"etranger") -> #ERROR!
A25: =TODAY()-3 -> 45924 | B25: =COUNTIFS(Responses!A:A,">="&A25,Responses!A:A,"<"&A25+1) -> #ERROR! | C25: =COUNTIFS(Responses!A:A,">="&A25,Responses!A:A,"<"&A25+1,Responses!C:C,">=70") -> #ERROR! | D25: =COUNTIFS(Responses!A:A,">="&A25,Responses!A:A,"<"&A25+1,Responses!L:L,"etranger") -> #ERROR!
A26: =TODAY()-2 -> 45925 | B26: =COUNTIFS(Responses!A:A,">="&A26,Responses!A:A,"<"&A26+1) -> #ERROR! | C26: =COUNTIFS(Responses!A:A,">="&A26,Responses!A:A,"<"&A26+1,Responses!C:C,">=70") -> #ERROR! | D26: =COUNTIFS(Responses!A:A,">="&A26,Responses!A:A,"<"&A26+1,Responses!L:L,"etranger") -> #ERROR!
A27: =TODAY()-1 -> 45926 | B27: =COUNTIFS(Responses!A:A,">="&A27,Responses!A:A,"<"&A27+1) -> #ERROR! | C27: =COUNTIFS(Responses!A:A,">="&A27,Responses!A:A,"<"&A27+1,Responses!C:C,">=70") -> #ERROR! | D27: =COUNTIFS(Responses!A:A,">="&A27,Responses!A:A,"<"&A27+1,Responses!L:L,"etranger") -> #ERROR!
A28: =TODAY() -> 45927 | B28: =COUNTIFS(Responses!A:A,">="&A28,Responses!A:A,"<"&A28+1) -> #ERROR! | C28: =COUNTIFS(Responses!A:A,">="&A28,Responses!A:A,"<"&A28+1,Responses!C:C,">=70") -> #ERROR! | D28: =COUNTIFS(Responses!A:A,">="&A28,Responses!A:A,"<"&A28+1,Responses!L:L,"etranger") -> #ERROR!

Sheet Hot Leads
A1: 🔥 HOT LEADS (Score ≥ 70)
A3: =IFERROR(FILTER(Responses!A:BB, Responses!C:C>=70, ROW(Responses!A:A)>1), "Aucun hot lead trouvé") -> #ERROR!

Sheet Diaspora
A1: 🌍 MEMBRES DIASPORA
A3: =IFERROR(FILTER(Responses!A:BB, Responses!L:L="etranger", ROW(Responses!A:A)>1), "Aucun membre diaspora trouvé") -> #ERROR!
